Workbook

Sheet Readme
A1: 2018 Central Park Squirrel Census Data Workbook - README
A3: OVERVIEW
A4: This workbook contains the original 2018 Central Park Squirrel Census data from NYC Open Data (~3,023 squirrel sightings), two synthetic datasets (Fake: pure random; Empirical Random: weighted sampling to match real distributions), detailed profile analyses for each, and a comparison dashboard. Purpose: demonstrate realistic vs. unrealistic synthetic data generation techniques and their impact on analysis results.
A6: DATA SHEETS
A7: Squirrel_Data
A8: • Original real dataset from NYC Open Data (2018 Central Park Squirrel Census).
A9: • ~3,023 sightings with location (X/Y, Lat/Long), demographics (Age, Primary Fur Color), behaviors (Running, Foraging, etc.), interactions, vocalizations. Columns A-AE. Excel Table: SquirrelData. Ground truth for distributions.
A11: Fake_Squirrel_Data
A12: • Synthetic dataset using pure random (uniform) randomization. ~1,000 rows, columns A-AC.
A13: • Values chosen independently without regard to real frequencies. Used to show unrealistic distributions.
A15: Empirical_Random_Squirrel_Data
A16: • Synthetic dataset generated with weighted random sampling based on real data distributions. ~1,000 rows, columns A-AC.
... A64: NYC Open Data - 2018 Central Park Squirrel Census - Squirrel Data
A65: =HYPERLINK("https://data.cityofnewyork.us/Environment/2018-Central-Park-Squirrel-Census-Squirrel-Data/vfnx-vebw", "Open in NYC Open Data") -> Open in NYC Open Data
A66: (Full URL: https://data.cityofnewyork.us/Environment/2018-Central-Park-Squirrel-Census-Squirrel-Data/vfnx-vebw)

Sheet Comparison
A1: Profile vs Fake Profile vs Empirical Random Profile Comparison
A3: KEY DISTRIBUTION COMPARISON (% of Total)
A4: Category | B4: Profile % | C4: Fake Profile % | D4: Diff (pp) | E4: Emp. Random % | F4: Diff (ER vs Real)
A5: PM Shift | B5: =Profile!C14 -> 0.55441614 | C5: ='Fake Profile'!C14 -> 0.527 | D5: =B5-C5 -> 0.027416143 | E5: ='Empirical Random Profile'!C14 -> 0.559 | F5: =B5-E5 -> -0.0045838571
A6: Adult Age | B6: =Profile!C19 -> 0.84948726 | C6: ='Fake Profile'!C19 -> 0.33 | D6: =B6-C6 -> 0.51948726 | E6: ='Empirical Random Profile'!C19 -> 0.88 | F6: =B6-E6 -> -0.030512736
A7: Gray Fur | B7: =Profile!C27 -> 0.81806153 | C7: ='Fake Profile'!C27 -> 0.332 | D7: =B7-C7 -> 0.48606153 | E7: ='Empirical Random Profile'!C27 -> 0.83 | F7: =B7-E7 -> -0.011938472
A8: Ground Plane Location | B8: =Profile!C35 -> 0.69996692 | C8: ='Fake Profile'!C35 -> 0.479 | D8: =B8-C8 -> 0.22096692 | E8: ='Empirical Random Profile'!C35 -> 0.712 | F8: =B8-E8 -> -0.01203308
A9: Foraging Behavior | B9: =Profile!C46 -> 0.47469401 | C9: ='Fake Profile'!C46 -> 0.501 | D9: =B9-C9 -> -0.026305987 | E9: ='Empirical Random Profile'!C46 -> 0.436 | F9: =B9-E9 -> 0.038694013
A10: Indifferent Interaction | B10: =Profile!C53 -> 0.48097916 | C10: ='Fake Profile'!C53 -> 0.503 | D10: =B10-C10 -> -0.02202084 | E10: ='Empirical Random Profile'!C53 -> 0.485 | F10: =B10-E10 -> -0.0040208402
A12: AGE COMPARISON
A13: Age | B13: Real Count | C13: Real % (3023) | D13: Fake Count | E13: Fake % (1000) | F13: Diff (pp) | G13: Emp. Random Count | H13: Emp. Random % (1000) | I13: Diff (ER vs Real)
A14: Adult | B14: =Profile!B19 -> 2568 | C14: =B14/3023 -> 0.84948726 | D14: ='Fake Profile'!B19 -> 330 | E14: =D14/1000 -> 0.33 | F14: =C14-E14 -> 0.51948726 | G14: ='Empirical Random Profile'!B19 -> 880 | H14: =G14/1000 -> 0.88 | I14: =C14-H14 -> -0.030512736
A15: Juvenile | B15: =Profile!B20 -> 330 | C15: =B15/3023 -> 0.10916308 | D15: ='Fake Profile'!B20 -> 337 | E15: =D15/1000 -> 0.337 | F15: =C15-E15 -> -0.22783692 | G15: ='Empirical Random Profile'!B20 -> 118 | H15: =G15/1000 -> 0.118 | I15: =C15-H15 -> -0.008836917
A16: Unknown (?) | B16: =Profile!B21 -> 4 | C16: =B16/3023 -> 0.0013231889 | D16: ='Fake Profile'!B21 -> 333 | E16: =D16/1000 -> 0.333 | F16: =C16-E16 -> -0.33167681 | G16: ='Empirical Random Profile'!B21 -> 2 | H16: =G16/1000 -> 0.002 | I16: =C16-H16 -> -0.00067681111
A17: (blank) | B17: =Profile!B22 -> 121 | C17: =B17/3023 -> 0.040026464 | D17: ='Fake Profile'!B22 -> 0 | E17: =D17/1000 -> 0 | F17: =C17-E17 -> 0.040026464 | G17: =0 -> 0 | H17: =G17/1000 -> 0 | I17: =C17-H17 -> 0.040026464
A18: Total | B18: =SUM(B14:B16) -> 2902 | C18: =SUM(C14:C16) -> 0.95997354 | D18: =SUM(D14:D16) -> 1000 | E18: =SUM(E14:E16) -> 1 | F18: =C18-E18 -> -0.040026464 | G18: ='Empirical Random Profile'!B23 -> 1000 | H18: =G18/1000 -> 1 | I18: =C18-H18 -> -0.040026464
A20: PRIMARY FUR COLOR COMPARISON
A21: Color | B21: Real Count | C21: Real % (3023) | D21: Fake Count | E21: Fake % (1000) | F21: Diff (pp) | G21: Emp. Random Count | H21: Emp. Random % (1000) | I21: Diff (ER vs Real)
A22: Gray | B22: =Profile!B27 -> 2473 | C22: =B22/3023 -> 0.81806153 | D22: ='Fake Profile'!B27 -> 332 | E22: =D22/1000 -> 0.332 | F22: =C22-E22 -> 0.48606153 | G22: ='Empirical Random Profile'!B27 -> 830 | H22: =G22/1000 -> 0.83 | I22: =C22-H22 -> -0.011938472
A23: Cinnamon | B23: =Profile!B28 -> 392 | C23: =B23/3023 -> 0.12967251 | D23: ='Fake Profile'!B28 -> 346 | E23: =D23/1000 -> 0.346 | F23: =C23-E23 -> -0.21632749 | G23: ='Empirical Random Profile'!B28 -> 138 | H23: =G23/1000 -> 0.138 | I23: =C23-H23 -> -0.0083274892
A24: Black | B24: =Profile!B29 -> 103 | C24: =B24/3023 -> 0.034072114 | D24: ='Fake Profile'!B29 -> 322 | E24: =D24/1000 -> 0.322 | F24: =C24-E24 -> -0.28792789 | G24: ='Empirical Random Profile'!B29 -> 32 | H24: =G24/1000 -> 0.032 | I24: =C24-H24 -> 0.0020721138
A25: Other/Blank | B25: =Profile!B30 -> 55 | C25: =B25/3023 -> 0.018193847 | D25: ='Fake Profile'!B30 -> 0 | E25: =D25/1000 -> 0 | F25: =C25-E25 -> 0.018193847 | G25: ='Empirical Random Profile'!B30 -> 0 | H25: =G25/1000 -> 0 | I25: =C25-H25 -> 0.018193847
A26: Total | B26: =SUM(B22:B25) -> 3023 | C26: =SUM(C22:C25) -> 1 | D26: =SUM(D22:D25) -> 1000 | E26: =SUM(E22:E25) -> 1 | F26: =C26-E26 -> 0 | G26: ='Empirical Random Profile'!B31 -> 1000 | H26: =G26/1000 -> 1 | I26: =C26-H26 -> 0
A28: BEHAVIORS & ACTIVITIES COMPARISON
A29: Behavior | B29: Real Count | C29: Real % (3023) | D29: Fake Count | E29: Fake % (1000) | F29: Diff (pp) | G29: Emp. Random Count | H29: Emp. Random % (1000) | I29: Diff (ER vs Real)
A30: Running | B30: =Profile!B42 -> 730 | C30: =B30/3023 -> 0.24148197 | D30: ='Fake Profile'!B42 -> 491 | E30: =D30/1000 -> 0.491 | F30: =C30-E30 -> -0.24951803 | G30: ='Empirical Random Profile'!B42 -> 261 | H30: =G30/1000 -> 0.261 | I30: =C30-H30 -> -0.019518028
A31: Chasing | B31: =Profile!B43 -> 279 | C31: =B31/3023 -> 0.092292425 | D31: ='Fake Profile'!B43 -> 471 | E31: =D31/1000 -> 0.471 | F31: =C31-E31 -> -0.37870758 | G31: ='Empirical Random Profile'!B43 -> 91 | H31: =G31/1000 -> 0.091 | I31: =C31-H31 -> 0.0012924247
A32: Climbing | B32: =Profile!B44 -> 658 | C32: =B32/3023 -> 0.21766457 | D32: ='Fake Profile'!B44 -> 490 | E32: =D32/1000 -> 0.49 | F32: =C32-E32 -> -0.27233543 | G32: ='Empirical Random Profile'!B44 -> 231 | H32: =G32/1000 -> 0.231 | I32: =C32-H32 -> -0.013335428
A33: Eating | B33: =Profile!B45 -> 760 | C33: =B33/3023 -> 0.25140589 | D33: ='Fake Profile'!B45 -> 513 | E33: =D33/1000 -> 0.513 | F33: =C33-E33 -> -0.26159411 | G33: ='Empirical Random Profile'!B45 -> 248 | H33: =G33/1000 -> 0.248 | I33: =C33-H33 -> 0.0034058882
A34: Foraging | B34: =Profile!B46 -> 1435 | C34: =B34/3023 -> 0.47469401 | D34: ='Fake Profile'!B46 -> 501 | E34: =D34/1000 -> 0.501 | F34: =C34-E34 -> -0.026305987 | G34: ='Empirical Random Profile'!B46 -> 436 | H34: =G34/1000 -> 0.436 | I34: =C34-H34 -> 0.038694013
A35: Kuks | B35: =Profile!B47 -> 102 | C35: =B35/3023 -> 0.033741317 | D35: ='Fake Profile'!B47 -> 510 | E35: =D35/1000 -> 0.51 | F35: =C35-E35 -> -0.47625868 | G35: ='Empirical Random Profile'!B47 -> 35 | H35: =G35/1000 -> 0.035 | I35: =C35-H35 -> -0.0012586834
A36: Quaas | B36: =Profile!B48 -> 50 | C36: =B36/3023 -> 0.016539861 | D36: ='Fake Profile'!B48 -> 497 | E36: =D36/1000 -> 0.497 | F36: =C36-E36 -> -0.48046014 | G36: ='Empirical Random Profile'!B48 -> 17 | H36: =G36/1000 -> 0.017 | I36: =C36-H36 -> -0.00046013893
A37: Moans | B37: =Profile!B49 -> 3 | C37: =B37/3023 -> 0.00099239166 | D37: ='Fake Profile'!B49 -> 479 | E37: =D37/1000 -> 0.479 | F37: =C37-E37 -> -0.47800761 | G37: ='Empirical Random Profile'!B49 -> 0 | H37: =G37/1000 -> 0 | I37: =C37-H37 -> 0.00099239166
A38: Tail flags | B38: =Profile!B50 -> 155 | C38: =B38/3023 -> 0.051273569 | D38: ='Fake Profile'!B50 -> 513 | E38: =D38/1000 -> 0.513 | F38: =C38-E38 -> -0.46172643 | G38: ='Empirical Random Profile'!B50 -> 50 | H38: =G38/1000 -> 0.05 | I38: =C38-H38 -> 0.0012735693
A39: Tail twitches | B39: =Profile!B51 -> 434 | C39: =B39/3023 -> 0.14356599 | D39: ='Fake Profile'!B51 -> 492 | E39: =D39/1000 -> 0.492 | F39: =C39-E39 -> -0.34843401 | G39: ='Empirical Random Profile'!B51 -> 143 | H39: =G39/1000 -> 0.143 | I39: =C39-H39 -> 0.00056599405
A40: Approaches | B40: =Profile!B52 -> 178 | C40: =B40/3023 -> 0.058881905 | D40: ='Fake Profile'!B52 -> 505 | E40: =D40/1000 -> 0.505 | F40: =C40-E40 -> -0.44611809 | G40: ='Empirical Random Profile'!B52 -> 48 | H40: =G40/1000 -> 0.048 | I40: =C40-H40 -> 0.010881905
A41: Indifferent | B41: =Profile!B53 -> 1454 | C41: =B41/3023 -> 0.48097916 | D41: ='Fake Profile'!B53 -> 503 | E41: =D41/1000 -> 0.503 | F41: =C41-E41 -> -0.02202084 | G41: ='Empirical Random Profile'!B53 -> 485 | H41: =G41/1000 -> 0.485 | I41: =C41-H41 -> -0.0040208402
... A43: Other Interactions | B43: =Profile!B55 -> 240 | C43: =B43/3023 -> 0.079391333 | D43: ='Fake Profile'!B55 -> 1000 | E43: =D43/1000 -> 1 | F43: =C43-E43 -> -0.92060867 | G43: ='Empirical Random Profile'!B55 -> 1000 | H43: =G43/1000 -> 1 | I43: =C43-H43 -> -0.92060867
A44: Total (sum of flags) | B44: =SUM(B30:B43) -> 7156 | C44: =SUM(C30:C43) -> 2.3671849 | D44: =SUM(D30:D43) -> 7448 | E44: =D44/1000 -> 7.448 | F44: =C44-E44 -> -5.0808151 | G44: ='Empirical Random Profile'!B56 -> 3262 | H44: =G44/1000 -> 3.262 | I44: =C44-H44 -> -0.89481508
A46: Chart Data - Age Distribution %
...

Sheet Profile
A1: 2018 Central Park Squirrel Census - Data Profile
A2: Source: NYC Open Data (2018 Central Park Squirrel Census) | 3,023 sightings in October 2018
A4: OVERVIEW
A5: Metric | B5: Value | C5: Notes / Assumptions
A6: Total Sightings | B6: =COUNTA(Squirrel_Data!C2:C3024) -> 3023 | C6: One row per squirrel sighting observed
A7: Unique Squirrel IDs | B7: {=SUMPRODUCT(1/COUNTIF(Squirrel_Data!C2:C3024,Squirrel_Data!C2:C3024&""))} -> 3018 | C7: Distinct count ~3018 (5 possible duplicate IDs in data)
A8: Unique Hectares | B8: {=ROUND(SUMPRODUCT(1/COUNTIF(Squirrel_Data!D2:D3024,Squirrel_Data!D2:D3024)),0)} -> 339 | C8: Park gridded into hectares (e.g., 37F)
A9: Census Period | B9: Early-Mid October 2018 | C9: Dates formatted as MMDDYYYY numeric
A11: SHIFT BREAKDOWN
A12: Shift | B12: Count | C12: Percentage
A13: AM | B13: =COUNTIF(Squirrel_Data!E2:E3024,"AM") -> 1347 | C13: =IF($B$6>0,B13/$B$6,0) -> 0.44558386
A14: PM | B14: =COUNTIF(Squirrel_Data!E2:E3024,"PM") -> 1676 | C14: =IF($B$6>0,B14/$B$6,0) -> 0.55441614
A15: Total | B15: =SUM(B13:B14) -> 3023 | C15: =SUM(C13:C14) -> 1
A17: AGE DISTRIBUTION
A18: Age | B18: Count | C18: Percentage
A19: Adult | B19: =COUNTIF(Squirrel_Data!H2:H3024,"Adult") -> 2568 | C19: =IF($B$6>0,B19/$B$6,0) -> 0.84948726
A20: Juvenile | B20: =COUNTIF(Squirrel_Data!H2:H3024,"Juvenile") -> 330 | C20: =IF($B$6>0,B20/$B$6,0) -> 0.10916308
A21: Unknown (?) | B21: =COUNTIF(Squirrel_Data!H2:H3024,"?") -> 4 | C21: =IF($B$6>0,B21/$B$6,0) -> 0.0013231889
A22: (blank) | B22: 121 | C22: =IF($B$6>0,B22/$B$6,0) -> 0.040026464
A23: Total | B23: =SUM(B19:B22) -> 3023 | C23: =SUM(C19:C22) -> 1
A25: PRIMARY FUR COLOR
A26: Color | B26: Count | C26: Percentage
A27: Gray | B27: =COUNTIF(Squirrel_Data!I2:I3024,"Gray") -> 2473 | C27: =IF($B$6>0,B27/$B$6,0) -> 0.81806153
A28: Cinnamon | B28: =COUNTIF(Squirrel_Data!I2:I3024,"Cinnamon") -> 392 | C28: =IF($B$6>0,B28/$B$6,0) -> 0.12967251
A29: Black | B29: =COUNTIF(Squirrel_Data!I2:I3024,"Black") -> 103 | C29: =IF($B$6>0,B29/$B$6,0) -> 0.034072114
A30: Other/Blank | B30: =$B$6-SUM(B27:B29) -> 55 | C30: =IF($B$6>0,B30/$B$6,0) -> 0.018193847
A31: Total | B31: =SUM(B27:B30) -> 3023
A33: LOCATION (Ground vs Above)
A34: Location | B34: Count | C34: Percentage
A35: Ground Plane | B35: =COUNTIF(Squirrel_Data!M2:M3024,"Ground Plane") -> 2116 | C35: =IF($B$6>0,B35/$B$6,0) -> 0.69996692
A36: Above Ground | B36: =COUNTIF(Squirrel_Data!M2:M3024,"Above Ground") -> 843 | C36: =IF($B$6>0,B36/$B$6,0) -> 0.27886206
A37: Other/Blank | B37: =$B$6-SUM(B35:B36) -> 64 | C37: =IF($B$6>0,B37/$B$6,0) -> 0.021171022
A38: Total | B38: =SUM(B35:B37) -> 3023 | C38: =SUM(C35:C37) -> 1
A40: BEHAVIORS & ACTIVITIES (Count of TRUE)
A41: Behavior | B41: Count | C41: % of Sightings
A42: Running (P) | B42: =COUNTIF(Squirrel_Data!P2:P3024,TRUE) -> 730 | C42: =IF($B$6>0,B42/$B$6,0) -> 0.24148197
A43: Chasing (Q) | B43: =COUNTIF(Squirrel_Data!Q2:Q3024,TRUE) -> 279 | C43: =IF($B$6>0,B43/$B$6,0) -> 0.092292425
A44: Climbing (R) | B44: =COUNTIF(Squirrel_Data!R2:R3024,TRUE) -> 658 | C44: =IF($B$6>0,B44/$B$6,0) -> 0.21766457
A45: Eating (S) | B45: =COUNTIF(Squirrel_Data!S2:S3024,TRUE) -> 760 | C45: =IF($B$6>0,B45/$B$6,0) -> 0.25140589
A46: Foraging (T) | B46: =COUNTIF(Squirrel_Data!T2:T3024,TRUE) -> 1435 | C46: =IF($B$6>0,B46/$B$6,0) -> 0.47469401
...

Sheet Fake Profile
A1: Fake Squirrel Census Data Profile (based on original structure)
A2: Source: Fake dataset based on NYC Open Data Squirrel Census | ~1000 sightings (rows 2-1001, cols A:AC)
A4: OVERVIEW
A5: Metric | B5: Value | C5: Notes / Assumptions
A6: Total Sightings | B6: =COUNTA(Fake_Squirrel_Data!AC2:AC1001) -> 1000 | C6: One row per squirrel sighting observed
A7: Unique Squirrel IDs | B7: {=SUMPRODUCT(1/COUNTIF(Fake_Squirrel_Data!AC2:AC1001,Fake_Squirrel_Data!AC2:AC1001&""))} -> 1000 | C7: Distinct count ~3018 (5 possible duplicate IDs in data)
A8: Unique Hectares | B8: {=ROUND(SUMPRODUCT(1/COUNTIF(Fake_Squirrel_Data!C2:C1001,Fake_Squirrel_Data!C2:C1001)),0)} -> 324 | C8: Park gridded into hectares (e.g., 37F)
A9: Census Period | B9: Early-Mid October 2018 | C9: Dates formatted as MMDDYYYY numeric
A11: SHIFT BREAKDOWN
A12: Shift | B12: Count | C12: Percentage
A13: AM | B13: =COUNTIF(Fake_Squirrel_Data!D2:D1001,"AM") -> 473 | C13: =IF($B$6>0,B13/$B$6,0) -> 0.473
A14: PM | B14: =COUNTIF(Fake_Squirrel_Data!D2:D1001,"PM") -> 527 | C14: =IF($B$6>0,B14/$B$6,0) -> 0.527
A15: Total | B15: =SUM(B13:B14) -> 1000 | C15: =SUM(C13:C14) -> 1
A17: AGE DISTRIBUTION
A18: Age | B18: Count | C18: Percentage
A19: Adult | B19: =COUNTIF(Fake_Squirrel_Data!G2:G1001,"Adult") -> 330 | C19: =IF($B$6>0,B19/$B$6,0) -> 0.33
A20: Juvenile | B20: =COUNTIF(Fake_Squirrel_Data!G2:G1001,"Juvenile") -> 337 | C20: =IF($B$6>0,B20/$B$6,0) -> 0.337
A21: Unknown (?) | B21: =COUNTIF(Fake_Squirrel_Data!G2:G1001,"?") -> 333 | C21: =IF($B$6>0,B21/$B$6,0) -> 0.333
A22: (blank) | B22: 0 | C22: 0
A23: Total | B23: =SUM(B19:B21) -> 1000 | C23: =SUM(C19:C21) -> 1
A25: PRIMARY FUR COLOR
A26: Color | B26: Count | C26: Percentage
A27: Gray | B27: =COUNTIF(Fake_Squirrel_Data!H2:H1001,"Gray") -> 332 | C27: =IF($B$6>0,B27/$B$6,0) -> 0.332
A28: Cinnamon | B28: =COUNTIF(Fake_Squirrel_Data!H2:H1001,"Cinnamon") -> 346 | C28: =IF($B$6>0,B28/$B$6,0) -> 0.346
A29: Black | B29: =COUNTIF(Fake_Squirrel_Data!H2:H1001,"Black") -> 322 | C29: =IF($B$6>0,B29/$B$6,0) -> 0.322
A30: Other/Blank | B30: =$B$6-SUM(B27:B29) -> 0 | C30: =IF($B$6>0,B30/$B$6,0) -> 0
A31: Total | B31: =SUM(B27:B30) -> 1000 | C31: =SUM(C27:C30) -> 1
A33: LOCATION (Ground vs Above)
A34: Location | B34: Count | C34: Percentage
A35: Ground Plane | B35: =COUNTIF(Fake_Squirrel_Data!L2:L1001,"Ground Plane") -> 479 | C35: =IF($B$6>0,B35/$B$6,0) -> 0.479
A36: Above Ground | B36: =COUNTIF(Fake_Squirrel_Data!L2:L1001,"Above Ground") -> 521 | C36: =IF($B$6>0,B36/$B$6,0) -> 0.521
A37: Other/Blank | B37: =$B$6-SUM(B35:B36) -> 0 | C37: =IF($B$6>0,B37/$B$6,0) -> 0
A38: Total | B38: =SUM(B35:B37) -> 1000 | C38: =SUM(C35:C37) -> 1
A40: BEHAVIORS & ACTIVITIES (Count of TRUE)
A41: Behavior | B41: Count | C41: % of Sightings
A42: Running (P) | B42: =COUNTIF(Fake_Squirrel_Data!O2:O1001,TRUE) -> 491 | C42: =IF($B$6>0,B42/$B$6,0) -> 0.491
A43: Chasing (Q) | B43: =COUNTIF(Fake_Squirrel_Data!P2:P1001,TRUE) -> 471 | C43: =IF($B$6>0,B43/$B$6,0) -> 0.471
A44: Climbing (R) | B44: =COUNTIF(Fake_Squirrel_Data!Q2:Q1001,TRUE) -> 490 | C44: =IF($B$6>0,B44/$B$6,0) -> 0.49
A45: Eating (S) | B45: =COUNTIF(Fake_Squirrel_Data!R2:R1001,TRUE) -> 513 | C45: =IF($B$6>0,B45/$B$6,0) -> 0.513
A46: Foraging (T) | B46: =COUNTIF(Fake_Squirrel_Data!S2:S1001,TRUE) -> 501 | C46: =IF($B$6>0,B46/$B$6,0) -> 0.501
...

Sheet Empirical Random Profile
A1: Empirical Random Squirrel Census Data Profile (based on original structure)
A2: Source: Empirical Random dataset based on NYC Open Data Squirrel Census | ~1000 sightings (rows 2-1001, cols A:AC)
A4: OVERVIEW
A5: Metric | B5: Value | C5: Notes / Assumptions
A6: Total Sightings | B6: =COUNTA(Empirical_Random_Squirrel_Data!AC2:AC1001) -> 1000 | C6: One row per squirrel sighting observed
A7: Unique Squirrel IDs | B7: {=SUMPRODUCT(1/COUNTIF(Empirical_Random_Squirrel_Data!AC2:AC1001,Empirical_Random_Squirrel_Data!AC2:AC1001&""))} -> 1000 | C7: Distinct count (live formula; ~1000 for this synthetic dataset)
A8: Unique Hectares | B8: {=ROUND(SUMPRODUCT(1/COUNTIF(Empirical_Random_Squirrel_Data!C2:C1001,Empirical_Random_Squirrel_Data!C2:C1001)),0)} -> 286 | C8: Park gridded into hectares (e.g., 37F)
A9: Census Period | B9: Early-Mid October 2018 | C9: Dates formatted as MMDDYYYY numeric
A11: SHIFT BREAKDOWN
A12: Shift | B12: Count | C12: Percentage
A13: AM | B13: =COUNTIF(Empirical_Random_Squirrel_Data!D2:D1001,"AM") -> 441 | C13: =IF($B$6>0,B13/$B$6,0) -> 0.441
A14: PM | B14: =COUNTIF(Empirical_Random_Squirrel_Data!D2:D1001,"PM") -> 559 | C14: =IF($B$6>0,B14/$B$6,0) -> 0.559
A15: Total | B15: =SUM(B13:B14) -> 1000 | C15: =SUM(C13:C14) -> 1
A17: AGE DISTRIBUTION
A18: Age | B18: Count | C18: Percentage
A19: Adult | B19: =COUNTIF(Empirical_Random_Squirrel_Data!G2:G1001,"Adult") -> 880 | C19: =IF($B$6>0,B19/$B$6,0) -> 0.88
A20: Juvenile | B20: =COUNTIF(Empirical_Random_Squirrel_Data!G2:G1001,"Juvenile") -> 118 | C20: =IF($B$6>0,B20/$B$6,0) -> 0.118
A21: Unknown (?) | B21: =COUNTIF(Empirical_Random_Squirrel_Data!G2:G1001,"?") -> 2 | C21: =IF($B$6>0,B21/$B$6,0) -> 0.002
A22: (blank) | B22: 0 | C22: 0
A23: Total | B23: =SUM(B19:B21) -> 1000 | C23: =SUM(C19:C21) -> 1
A25: PRIMARY FUR COLOR
A26: Color | B26: Count | C26: Percentage
A27: Gray | B27: =COUNTIF(Empirical_Random_Squirrel_Data!H2:H1001,"Gray") -> 830 | C27: =IF($B$6>0,B27/$B$6,0) -> 0.83
A28: Cinnamon | B28: =COUNTIF(Empirical_Random_Squirrel_Data!H2:H1001,"Cinnamon") -> 138 | C28: =IF($B$6>0,B28/$B$6,0) -> 0.138
A29: Black | B29: =COUNTIF(Empirical_Random_Squirrel_Data!H2:H1001,"Black") -> 32 | C29: =IF($B$6>0,B29/$B$6,0) -> 0.032
A30: Other/Blank | B30: =$B$6-SUM(B27:B29) -> 0 | C30: =IF($B$6>0,B30/$B$6,0) -> 0
A31: Total | B31: =SUM(B27:B30) -> 1000 | C31: =SUM(C27:C30) -> 1
A33: LOCATION (Ground vs Above)
A34: Location | B34: Count | C34: Percentage
A35: Ground Plane | B35: =COUNTIF(Empirical_Random_Squirrel_Data!L2:L1001,"Ground Plane") -> 712 | C35: =IF($B$6>0,B35/$B$6,0) -> 0.712
A36: Above Ground | B36: =COUNTIF(Empirical_Random_Squirrel_Data!L2:L1001,"Above Ground") -> 288 | C36: =IF($B$6>0,B36/$B$6,0) -> 0.288
A37: Other/Blank | B37: =$B$6-SUM(B35:B36) -> 0 | C37: =IF($B$6>0,B37/$B$6,0) -> 0
A38: Total | B38: =SUM(B35:B37) -> 1000 | C38: =SUM(C35:C37) -> 1
A40: BEHAVIORS & ACTIVITIES (Count of TRUE)
A41: Behavior | B41: Count | C41: % of Sightings
A42: Running (P) | B42: =COUNTIF(Empirical_Random_Squirrel_Data!O2:O1001,TRUE) -> 261 | C42: =IF($B$6>0,B42/$B$6,0) -> 0.261
A43: Chasing (Q) | B43: =COUNTIF(Empirical_Random_Squirrel_Data!P2:P1001,TRUE) -> 91 | C43: =IF($B$6>0,B43/$B$6,0) -> 0.091
A44: Climbing (R) | B44: =COUNTIF(Empirical_Random_Squirrel_Data!Q2:Q1001,TRUE) -> 231 | C44: =IF($B$6>0,B44/$B$6,0) -> 0.231
A45: Eating (S) | B45: =COUNTIF(Empirical_Random_Squirrel_Data!R2:R1001,TRUE) -> 248 | C45: =IF($B$6>0,B45/$B$6,0) -> 0.248
A46: Foraging (T) | B46: =COUNTIF(Empirical_Random_Squirrel_Data!S2:S1001,TRUE) -> 436 | C46: =IF($B$6>0,B46/$B$6,0) -> 0.436
...

Sheet Squirrel_Data
A1: X | B1: Y | C1: Unique Squirrel ID | D1: Hectare | E1: Shift | F1: Date | G1: Hectare Squirrel Number | H1: Age | I1: Primary Fur Color | J1: Highlight Fur Color | K1: Combination of Primary and Highlight Color | L1: Color notes | M1: Location | N1: Above Ground Sighter Measurement | O1: Specific Location | P1: Running | Q1: Chasing | R1: Climbing | S1: Eating | T1: Foraging | U1: Other Activities | V1: Kuks | W1: Quaas | X1: Moans | Y1: Tail flags | Z1: Tail twitches | AA1: Approaches | AB1: Indifferent | AC1: Runs from | AD1: Other Interactions | AE1: Lat/Long
A2: -73.956134 | B2: 40.794082 | C2: 37F-PM-1014-03 | D2: 37F | E2: PM | F2: 10142018 | G2: 3 | K2: + | P2: FALSE | Q2: FALSE | R2: FALSE | S2: FALSE | T2: FALSE | V2: FALSE | W2: FALSE | X2: FALSE | Y2: FALSE | Z2: FALSE | AA2: FALSE | AB2: FALSE | AC2: FALSE | AE2: POINT (-73.9561344937861 40.7940823884086)
A3: -73.968857 | B3: 40.783783 | C3: 21B-AM-1019-04 | D3: 21B | E3: AM | F3: 10192018 | G3: 4 | K3: + | P3: FALSE | Q3: FALSE | R3: FALSE | S3: FALSE | T3: FALSE | V3: FALSE | W3: FALSE | X3: FALSE | Y3: FALSE | Z3: FALSE | AA3: FALSE | AB3: FALSE | AC3: FALSE | AE3: POINT (-73.9688574691102 40.7837825208444)
A4: -73.974281 | B4: 40.775534 | C4: 11B-PM-1014-08 | D4: 11B | E4: PM | F4: 10142018 | G4: 8 | I4: Gray | K4: Gray+ | M4: Above Ground | N4: 10 | P4: FALSE | Q4: TRUE | R4: FALSE | S4: FALSE | T4: FALSE | V4: FALSE | W4: FALSE | X4: FALSE | Y4: FALSE | Z4: FALSE | AA4: FALSE | AB4: FALSE | AC4: FALSE | AE4: POINT (-73.97428114848522 40.775533619083)
A5: -73.959641 | B5: 40.790313 | C5: 32E-PM-1017-14 | D5: 32E | E5: PM | F5: 10172018 | G5: 14 | H5: Adult | I5: Gray | K5: Gray+ | L5: Nothing selected as Primary. Gray selected as Highlights. Made executive adjustments. | P5: FALSE | Q5: FALSE | R5: FALSE | S5: TRUE | T5: TRUE | V5: FALSE | W5: FALSE | X5: FALSE | Y5: FALSE | Z5: FALSE | AA5: FALSE | AB5: FALSE | AC5: TRUE | AE5: POINT (-73.9596413903948 40.7903128889029)
A6: -73.970268 | B6: 40.776213 | C6: 13E-AM-1017-05 | D6: 13E | E6: AM | F6: 10172018 | G6: 5 | H6: Adult | I6: Gray | J6: Cinnamon | K6: Gray+Cinnamon | M6: Above Ground | O6: on tree stump | P6: FALSE | Q6: FALSE | R6: FALSE | S6: FALSE | T6: TRUE | V6: FALSE | W6: FALSE | X6: FALSE | Y6: FALSE | Z6: FALSE | AA6: FALSE | AB6: FALSE | AC6: FALSE | AE6: POINT (-73.9702676472613 40.7762126854894)
A7: -73.968361 | B7: 40.772591 | C7: 11H-AM-1010-03 | D7: 11H | E7: AM | F7: 10102018 | G7: 3 | H7: Adult | I7: Cinnamon | J7: White | K7: Cinnamon+White | P7: FALSE | Q7: FALSE | R7: FALSE | S7: FALSE | T7: TRUE | V7: FALSE | W7: FALSE | X7: FALSE | Y7: FALSE | Z7: TRUE | AA7: FALSE | AB7: TRUE | AC7: FALSE | AE7: POINT (-73.9683613516225 40.7725908847499)
A8: -73.95412 | B8: 40.793181 | C8: 36H-AM-1010-02 | D8: 36H | E8: AM | F8: 10102018 | G8: 2 | H8: Adult | I8: Gray | K8: Gray+ | L8: just outside hectare | M8: Ground Plane | N8: FALSE | P8: FALSE | Q8: FALSE | R8: FALSE | S8: FALSE | T8: TRUE | V8: FALSE | W8: FALSE | X8: FALSE | Y8: FALSE | Z8: FALSE | AA8: FALSE | AB8: FALSE | AC8: FALSE | AE8: POINT (-73.9541201789795 40.7931811701082)
A9: -73.958269 | B9: 40.791737 | C9: 33F-AM-1008-02 | D9: 33F | E9: AM | F9: 10082018 | G9: 2 | H9: Adult | I9: Gray | K9: Gray+ | M9: Ground Plane | N9: FALSE | P9: FALSE | Q9: FALSE | R9: FALSE | S9: FALSE | T9: TRUE | V9: FALSE | W9: FALSE | X9: FALSE | Y9: FALSE | Z9: FALSE | AA9: FALSE | AB9: TRUE | AC9: FALSE | AE9: POINT (-73.9582694312289 40.7917367820255)
A10: -73.967429 | B10: 40.782972 | C10: 21C-PM-1006-01 | D10: 21C | E10: PM | F10: 10062018 | G10: 1 | H10: Adult | I10: Gray | K10: Gray+ | M10: Ground Plane | N10: FALSE | P10: FALSE | Q10: FALSE | R10: FALSE | S10: FALSE | T10: FALSE | V10: FALSE | W10: FALSE | X10: FALSE | Y10: TRUE | Z10: TRUE | AA10: FALSE | AB10: FALSE | AC10: FALSE | AE10: POINT (-73.9674285955293 40.7829723919744)
A11: -73.97225 | B11: 40.774288 | C11: 11D-AM-1010-03 | D11: 11D | E11: AM | F11: 10102018 | G11: 3 | H11: Adult | I11: Gray | J11: Cinnamon | K11: Gray+Cinnamon | M11: Above Ground | N11: 30 | P11: FALSE | Q11: FALSE | R11: TRUE | S11: FALSE | T11: FALSE | U11: grooming | V11: FALSE | W11: FALSE | X11: FALSE | Y11: FALSE | Z11: FALSE | AA11: FALSE | AB11: TRUE | AC11: FALSE | AE11: POINT (-73.9722500196844 40.7742879599026)
A12: -73.969506 | B12: 40.782351 | C12: 20B-PM-1013-05 | D12: 20B | E12: PM | F12: 10132018 | G12: 5 | H12: Adult | I12: Gray | J12: White | K12: Gray+White | M12: Ground Plane | N12: FALSE | P12: FALSE | Q12: FALSE | R12: FALSE | S12: FALSE | T12: TRUE | V12: FALSE | W12: FALSE | X12: FALSE | Y12: FALSE | Z12: FALSE | AA12: FALSE | AB12: TRUE | AC12: FALSE | AE12: POINT (-73.9695063535333 40.7823507678183)
A13: -73.964003 | B13: 40.782031 | C13: 22F-PM-1014-06 | D13: 22F | E13: PM | F13: 10142018 | G13: 6 | H13: Adult | I13: Gray | K13: Gray+ | M13: Ground Plane | N13: FALSE | P13: TRUE | Q13: FALSE | R13: FALSE | S13: FALSE | T13: FALSE | V13: FALSE | W13: FALSE | X13: FALSE | Y13: FALSE | Z13: TRUE | AA13: FALSE | AB13: TRUE | AC13: FALSE | AE13: POINT (-73.9640032826529 40.7820309825448)
A14: -73.953217 | B14: 40.791967 | C14: 36I-PM-1007-01 | D14: 36I | E14: PM | F14: 10072018 | G14: 1 | H14: Adult | I14: Gray | J14: Cinnamon | K14: Gray+Cinnamon | M14: Ground Plane | N14: FALSE | P14: FALSE | Q14: FALSE | R14: FALSE | S14: FALSE | T14: TRUE | V14: FALSE | W14: FALSE | X14: FALSE | Y14: FALSE | Z14: FALSE | AA14: FALSE | AB14: TRUE | AC14: FALSE | AE14: POINT (-73.9532170504865 40.7919669739962)
A15: -73.97686 | B15: 40.77028 | C15: 5C-PM-1010-09 | D15: 05C | E15: PM | F15: 10102018 | G15: 9 | H15: Adult | I15: Cinnamon | J15: Gray | K15: Cinnamon+Gray | M15: Ground Plane | N15: FALSE | P15: TRUE | Q15: FALSE | R15: FALSE | S15: FALSE | T15: FALSE | V15: FALSE | W15: FALSE | X15: FALSE | Y15: FALSE | Z15: FALSE | AA15: FALSE | AB15: FALSE | AC15: FALSE | AE15: POINT (-73.9768603630674 40.7702795904962)
A16: -73.970611 | B16: 40.769812 | C16: 7H-AM-1006-05 | D16: 07H | E16: AM | F16: 10062018 | G16: 5 | H16: Adult | I16: Gray | J16: Cinnamon | K16: Gray+Cinnamon | M16: Above Ground | N16: 10 | P16: FALSE | Q16: TRUE | R16: FALSE | S16: FALSE | T16: FALSE | V16: FALSE | W16: FALSE | X16: FALSE | Y16: FALSE | Z16: FALSE | AA16: FALSE | AB16: TRUE | AC16: FALSE | AE16: POINT (-73.9706105896967 40.7698124821507)
A17: -73.970378 | B17: 40.778753 | C17: 16C-PM-1018-03 | D17: 16C | E17: PM | F17: 10182018 | G17: 3 | H17: Adult | I17: Gray | J17: Cinnamon, White | K17: Gray+Cinnamon, White | M17: Above Ground | N17: 6 | P17: TRUE | Q17: FALSE | R17: FALSE | S17: TRUE | T17: TRUE | V17: FALSE | W17: FALSE | X17: FALSE | Y17: FALSE | Z17: FALSE | AA17: FALSE | AB17: TRUE | AC17: FALSE | AE17: POINT (-73.9703781726172 40.7787526130321)
A18: -73.970393 | B18: 40.776503 | C18: 14E-AM-1008-23 | D18: 14E | E18: AM | F18: 10082018 | G18: 23 | H18: Adult | I18: Gray | K18: Gray+ | M18: Ground Plane | N18: FALSE | P18: FALSE | Q18: FALSE | R18: FALSE | S18: FALSE | T18: TRUE | U18: walking | V18: FALSE | W18: FALSE | X18: FALSE | Y18: FALSE | Z18: FALSE | AA18: FALSE | AB18: TRUE | AC18: FALSE | AE18: POINT (-73.9703925210471 40.7765032004992)
A19: -73.963818 | B19: 40.792417 | C19: 32A-PM-1013-03 | D19: 32A | E19: PM | F19: 10132018 | G19: 3 | H19: Juvenile | I19: Gray | J19: Cinnamon | K19: Gray+Cinnamon | M19: Ground Plane | N19: FALSE | P19: FALSE | Q19: FALSE | R19: FALSE | S19: TRUE | T19: FALSE | V19: FALSE | W19: FALSE | X19: FALSE | Y19: FALSE | Z19: FALSE | AA19: FALSE | AB19: TRUE | AC19: FALSE | AE19: POINT (-73.9638179439747 40.7924173263904)
A20: -73.958407 | B20: 40.791381 | C20: 33F-AM-1008-01 | D20: 33F | E20: AM | F20: 10082018 | G20: 1 | H20: Adult | I20: Gray | K20: Gray+ | M20: Ground Plane | N20: FALSE | P20: FALSE | Q20: FALSE | R20: FALSE | S20: FALSE | T20: FALSE | U20: moving slowly | V20: FALSE | W20: FALSE | X20: FALSE | Y20: FALSE | Z20: FALSE | AA20: FALSE | AB20: TRUE | AC20: FALSE | AE20: POINT (-73.9584070974734 40.7913812490557)
A21: -73.967113 | B21: 40.778486 | C21: 17F-AM-1007-07 | D21: 17F | E21: AM | F21: 10072018 | G21: 7 | H21: Adult | I21: Gray | J21: White | K21: Gray+White | M21: Above Ground | N21: 24 | P21: TRUE | Q21: FALSE | R21: FALSE | S21: FALSE | T21: FALSE | V21: FALSE | W21: FALSE | X21: FALSE | Y21: TRUE | Z21: FALSE | AA21: FALSE | AB21: TRUE | AC21: FALSE | AE21: POINT (-73.9671130680114 40.7784859700171)
A22: -73.964987 | B22: 40.776493 | C22: 16I-AM-1008-01 | D22: 16I | E22: AM | F22: 10082018 | G22: 1 | H22: Adult | I22: Cinnamon | J22: Gray, White | K22: Cinnamon+Gray, White | M22: Ground Plane | N22: FALSE | P22: FALSE | Q22: FALSE | R22: FALSE | S22: FALSE | T22: TRUE | V22: FALSE | W22: FALSE | X22: FALSE | Y22: FALSE | Z22: TRUE | AA22: FALSE | AB22: TRUE | AC22: FALSE | AE22: POINT (-73.9649866016038 40.7764929694457)
A23: -73.967063 | B23: 40.773499 | C23: 12I-AM-1013-01 | D23: 12I | E23: AM | F23: 10132018 | G23: 1 | H23: Adult | I23: Cinnamon | J23: White | K23: Cinnamon+White | M23: Ground Plane | N23: FALSE | O23: on tree roots | P23: FALSE | Q23: FALSE | R23: FALSE | S23: FALSE | T23: FALSE | U23: sitting | V23: FALSE | W23: FALSE | X23: FALSE | Y23: FALSE | Z23: TRUE | AA23: FALSE | AB23: FALSE | AC23: TRUE | AE23: POINT (-73.9670628558161 40.77349914209411)
A24: -73.958737 | B24: 40.790852 | C24: 32F-PM-1008-07 | D24: 32F | E24: PM | F24: 10082018 | G24: 7 | H24: Adult | I24: Gray | K24: Gray+ | M24: Ground Plane | N24: FALSE | P24: TRUE | Q24: TRUE | R24: FALSE | S24: FALSE | T24: TRUE | V24: FALSE | W24: FALSE | X24: FALSE | Y24: FALSE | Z24: FALSE | AA24: FALSE | AB24: TRUE | AC24: FALSE | AE24: POINT (-73.958736593111 40.7908524370626)
A25: -73.967179 | B25: 40.786735 | C25: 25A-AM-1013-04 | D25: 25A | E25: AM | F25: 10132018 | G25: 4 | I25: Gray | J25: White | K25: Gray+White | M25: Ground Plane | N25: FALSE | P25: FALSE | Q25: FALSE | R25: FALSE | S25: FALSE | T25: TRUE | V25: FALSE | W25: FALSE | X25: FALSE | Y25: FALSE | Z25: FALSE | AA25: FALSE | AB25: FALSE | AC25: TRUE | AE25: POINT (-73.9671786715256 40.7867352791232)
A26: -73.969294 | B26: 40.776954 | C26: 15E-AM-1013-01 | D26: 15E | E26: AM | F26: 10132018 | G26: 1 | H26: Adult | I26: Gray | J26: White | K26: Gray+White | M26: Ground Plane | N26: FALSE | P26: TRUE | Q26: FALSE | R26: FALSE | S26: FALSE | T26: TRUE | V26: FALSE | W26: FALSE | X26: FALSE | Y26: FALSE | Z26: FALSE | AA26: FALSE | AB26: FALSE | AC26: FALSE | AE26: POINT (-73.9692943291611 40.7769536102488)
A27: -73.954005 | B27: 40.795245 | C27: 39G-PM-1013-06 | D27: 39G | E27: PM | F27: 10132018 | G27: 6 | H27: Adult | I27: Gray | J27: Cinnamon | K27: Gray+Cinnamon | M27: Ground Plane | N27: FALSE | P27: TRUE | Q27: FALSE | R27: FALSE | S27: FALSE | T27: FALSE | V27: FALSE | W27: FALSE | X27: FALSE | Y27: FALSE | Z27: FALSE | AA27: FALSE | AB27: FALSE | AC27: FALSE | AE27: POINT (-73.9540054100539 40.7952445999836)
A28: -73.957653 | B28: 40.786866 | C28: 29I-PM-1007-01 | D28: 29I | E28: PM | F28: 10072018 | G28: 1 | I28: Gray | J28: Cinnamon | K28: Gray+Cinnamon | M28: Ground Plane | N28: FALSE | P28: FALSE | Q28: FALSE | R28: FALSE | S28: TRUE | T28: TRUE | V28: FALSE | W28: FALSE | X28: FALSE | Y28: FALSE | Z28: FALSE | AA28: FALSE | AB28: FALSE | AC28: FALSE | AE28: POINT (-73.9576530157255 40.7868659490397)
A29: -73.973803 | B29: 40.771185 | C29: 7E-AM-1006-02 | D29: 07E | E29: AM | F29: 10062018 | G29: 2 | H29: Adult | I29: Gray | K29: Gray+ | M29: Ground Plane | N29: FALSE | O29: under a tree | P29: FALSE | Q29: FALSE | R29: FALSE | S29: TRUE | T29: FALSE | V29: FALSE | W29: FALSE | X29: FALSE | Y29: FALSE | Z29: FALSE | AA29: FALSE | AB29: FALSE | AC29: FALSE | AE29: POINT (-73.9738033257473 40.7711846894166)
A30: -73.97044 | B30: 40.779897 | C30: 17C-PM-1013-05 | D30: 17C | E30: PM | F30: 10132018 | G30: 5 | H30: Adult | I30: Gray | K30: Gray+ | M30: Ground Plane | N30: FALSE | P30: FALSE | Q30: FALSE | R30: FALSE | S30: TRUE | T30: FALSE | U30: eating (ate upside down on a tree â€” #jealous) | V30: FALSE | W30: FALSE | X30: FALSE | Y30: FALSE | Z30: FALSE | AA30: FALSE | AB30: TRUE | AC30: FALSE | AE30: POINT (-73.9704402681017 40.77989656212031)
A31: -73.975698 | B31: 40.77539 | C31: 10A-PM-1014-01 | D31: 10A | E31: PM | F31: 10142018 | G31: 1 | H31: Adult | I31: Gray | J31: Black, Cinnamon, White | K31: Gray+Black, Cinnamon, White | L31: Gray & White selected as Primary. Black & Cinnamon selected as Highlights. Made executive adjustments. | M31: Ground Plane | N31: FALSE | O31: in b/w trees | P31: FALSE | Q31: FALSE | R31: FALSE | S31: FALSE | T31: TRUE | V31: FALSE | W31: FALSE | X31: FALSE | Y31: FALSE | Z31: TRUE | AA31: FALSE | AB31: TRUE | AC31: FALSE | AE31: POINT (-73.9756976076707 40.7753897331918)
A32: -73.966244 | B32: 40.789038 | C32: 28A-PM-1007-05 | D32: 28A | E32: PM | F32: 10072018 | G32: 5 | H32: Adult | I32: Cinnamon | K32: Cinnamon+ | M32: Ground Plane | N32: FALSE | P32: TRUE | Q32: FALSE | R32: FALSE | S32: FALSE | T32: TRUE | V32: FALSE | W32: FALSE | X32: FALSE | Y32: FALSE | Z32: TRUE | AA32: FALSE | AB32: FALSE | AC32: TRUE | AE32: POINT (-73.9662438996681 40.7890381809441)
A33: -73.964315 | B33: 40.782082 | C33: 22F-PM-1014-05 | D33: 22F | E33: PM | F33: 10142018 | G33: 5 | H33: Adult | I33: Gray | J33: Cinnamon | K33: Gray+Cinnamon | M33: Ground Plane | N33: FALSE | P33: FALSE | Q33: FALSE | R33: FALSE | S33: FALSE | T33: FALSE | V33: FALSE | W33: FALSE | X33: FALSE | Y33: FALSE | Z33: FALSE | AA33: FALSE | AB33: FALSE | AC33: FALSE | AE33: POINT (-73.9643153920428 40.7820818516957)
A34: -73.974207 | B34: 40.775796 | C34: 12B-AM-1007-01 | D34: 12B | E34: AM | F34: 10072018 | G34: 1 | H34: Adult | I34: Gray | J34: Cinnamon | K34: Gray+Cinnamon | M34: Ground Plane | N34: FALSE | P34: FALSE | Q34: TRUE | R34: FALSE | S34: FALSE | T34: FALSE | V34: FALSE | W34: FALSE | X34: FALSE | Y34: TRUE | Z34: FALSE | AA34: FALSE | AB34: TRUE | AC34: FALSE | AE34: POINT (-73.9742073452913 40.7757957380463)
A35: -73.971615 | B35: 40.781391 | C35: 18A-PM-1018-01 | D35: 18A | E35: PM | F35: 10182018 | G35: 1 | H35: Adult | I35: Gray | K35: Gray+ | M35: Above Ground | N35: 30 | P35: FALSE | Q35: FALSE | R35: TRUE | S35: FALSE | T35: FALSE | V35: FALSE | W35: FALSE | X35: FALSE | Y35: FALSE | Z35: FALSE | AA35: FALSE | AB35: FALSE | AC35: FALSE | AE35: POINT (-73.9716147061553 40.7813911036179)
A36: -73.95657 | B36: 40.790256 | C36: 33H-AM-1019-02 | D36: 33H | E36: AM | F36: 10192018 | G36: 2 | H36: Juvenile | I36: Gray | J36: Cinnamon | K36: Gray+Cinnamon | M36: Ground Plane | N36: FALSE | P36: FALSE | Q36: FALSE | R36: FALSE | S36: FALSE | T36: FALSE | U36: wrestling with mother | V36: FALSE | W36: FALSE | X36: FALSE | Y36: FALSE | Z36: FALSE | AA36: FALSE | AB36: FALSE | AC36: FALSE | AE36: POINT (-73.9565700386162 40.7902561000937)
A37: -73.953541 | B37: 40.792871 | C37: 36H-PM-1008-02 | D37: 36H | E37: PM | F37: 10082018 | G37: 2 | H37: Adult | I37: Gray | K37: Gray+ | M37: Ground Plane | N37: FALSE | P37: FALSE | Q37: FALSE | R37: FALSE | S37: FALSE | T37: TRUE | V37: FALSE | W37: FALSE | X37: FALSE | Y37: FALSE | Z37: FALSE | AA37: FALSE | AB37: TRUE | AC37: FALSE | AE37: POINT (-73.9535410657077 40.79287117600611)
A38: -73.963916 | B38: 40.789177 | C38: 29C-AM-1007-06 | D38: 29C | E38: AM | F38: 10072018 | G38: 6 | H38: Adult | I38: Gray | J38: Cinnamon | K38: Gray+Cinnamon | M38: Ground Plane | N38: FALSE | P38: TRUE | Q38: FALSE | R38: FALSE | S38: FALSE | T38: FALSE | V38: FALSE | W38: FALSE | X38: FALSE | Y38: FALSE | Z38: FALSE | AA38: FALSE | AB38: FALSE | AC38: TRUE | AE38: POINT (-73.9639159298446 40.7891774637988)
A39: -73.957956 | B39: 40.795934 | C39: 38C-PM-1014-09 | D39: 38C | E39: PM | F39: 10142018 | G39: 9 | H39: Adult | I39: Black | K39: Black+ | M39: Ground Plane | N39: FALSE | P39: FALSE | Q39: FALSE | R39: FALSE | S39: TRUE | T39: FALSE | V39: FALSE | W39: FALSE | X39: FALSE | Y39: FALSE | Z39: FALSE | AA39: TRUE | AB39: FALSE | AC39: FALSE | AE39: POINT (-73.9579564338627 40.7959337795027)
A40: -73.957465 | B40: 40.789251 | C40: 31H-PM-1008-02 | D40: 31H | E40: PM | F40: 10082018 | G40: 2 | H40: Juvenile | I40: Gray | J40: Cinnamon | K40: Gray+Cinnamon | M40: Above Ground | N40: 8 | P40: TRUE | Q40: FALSE | R40: TRUE | S40: FALSE | T40: FALSE | V40: FALSE | W40: FALSE | X40: FALSE | Y40: FALSE | Z40: TRUE | AA40: FALSE | AB40: TRUE | AC40: FALSE | AE40: POINT (-73.9574648097543 40.78925084286221)
...

Sheet Fake_Squirrel_Data
A1: X | B1: Y | C1: Hectare | D1: Shift | E1: Date | F1: Hectare Squirrel Number | G1: Age | H1: Primary Fur Color | I1: Highlight Fur Color | J1: Combination of Primary and Highlight Color | K1: Color notes | L1: Location | M1: Above Ground Sighter Measurement | N1: Specific Location | O1: Running | P1: Chasing | Q1: Climbing | R1: Eating | S1: Foraging | T1: Kuks | U1: Quaas | V1: Moans | W1: Tail flags | X1: Tail twitches | Y1: Approaches | Z1: Indifferent | AA1: Runs from | AB1: Other Activities | AC1: Unique Squirrel ID
A2: -73.969384 | B2: 40.771429 | C2: 36C | D2: AM | E2: 43389 | F2: 12 | G2: ? | H2: Gray | I2: Black | J2: Gray+White | K2: Short tail | L2: Ground Plane | M2: FALSE | N2: Running down tree | O2: FALSE | P2: FALSE | Q2: TRUE | R2: TRUE | S2: TRUE | T2: FALSE | U2: TRUE | V2: FALSE | W2: FALSE | X2: TRUE | Y2: FALSE | Z2: FALSE | AA2: FALSE | AB2: jumping between branches | AC2: 36C-AM-835712-25
A3: -73.951271 | B3: 40.78399 | C3: 06A | D3: PM | E3: 43388 | F3: 1 | G3: Juvenile | H3: Black | I3: Gray, Black | J3: Gray+Black, Cinnamon | K3: Gray, Black, & Cinnamon selected as Primary. Cinnamon & White selected as Highlights. Made executive adjustments. | L3: Above Ground | M3: 12 | N3: in grass by light post | O3: TRUE | P3: TRUE | Q3: FALSE | R3: TRUE | S3: FALSE | T3: TRUE | U3: FALSE | V3: TRUE | W3: TRUE | X3: FALSE | Y3: TRUE | Z3: TRUE | AA3: TRUE | AB3: laid down on the branch | AC3: 06A-PM-390530-29
A4: -73.958147 | B4: 40.795645 | C4: 36C | D4: AM | E4: 43390 | F4: 23 | G4: Adult | H4: Black | I4: Gray, Black | J4: Gray+ | K4: Cinnamon head | L4: Ground Plane | M4: FALSE | N4: lawn moving east over Park path | O4: FALSE | P4: TRUE | Q4: TRUE | R4: TRUE | S4: TRUE | T4: TRUE | U4: FALSE | V4: TRUE | W4: FALSE | X4: TRUE | Y4: FALSE | Z4: TRUE | AA4: TRUE | AB4: walking on branch | AC4: 36C-AM-690940-20
A5: -73.962339 | B5: 40.790691 | C5: 31I | D5: PM | E5: 43387 | F5: 22 | G5: Juvenile | H5: Black | I5: Cinnamon, White | J5: Black+ | K5: Gray & Cinnamon selected as Primary: "much browner, like 1/2 & 1/2". | L5: Above Ground | M5: 7 | N5: Ground then up tree | O5: FALSE | P5: TRUE | Q5: FALSE | R5: FALSE | S5: TRUE | T5: FALSE | U5: FALSE | V5: TRUE | W5: FALSE | X5: FALSE | Y5: TRUE | Z5: TRUE | AA5: TRUE | AB5: hopping around grass | AC5: 31I-PM-984555-05
A6: -73.976254 | B6: 40.793308 | C6: 39A | D6: AM | E6: 43384 | F6: 8 | G6: Adult | H6: Cinnamon | I6: Black, Cinnamon | J6: Cinnamon+Gray, Black | K6: vid! | L6: Above Ground | M6: 20 | N6: Fence | O6: FALSE | P6: FALSE | Q6: FALSE | R6: TRUE | S6: FALSE | T6: FALSE | U6: FALSE | V6: FALSE | W6: FALSE | X6: FALSE | Y6: TRUE | Z6: FALSE | AA6: TRUE | AB6: playing w/ #8 | AC6: 39A-AM-999915-29
A7: -73.976255 | B7: 40.788105 | C7: 25B | D7: AM | E7: 43390 | F7: 5 | G7: Juvenile | H7: Black | I7: Black, Cinnamon, White | J7: Cinnamon+Gray, White | K7: Cinnamon & White selected as Primary. Cinnamon & White selected as Highlights. Made executive adjustments. | L7: Ground Plane | M7: FALSE | N7: in grass | O7: FALSE | P7: FALSE | Q7: FALSE | R7: TRUE | S7: TRUE | T7: TRUE | U7: FALSE | V7: TRUE | W7: FALSE | X7: TRUE | Y7: FALSE | Z7: TRUE | AA7: TRUE | AB7: playing w/ #6 | AC7: 25B-AM-236659-05
A8: -73.979333 | B8: 40.789284 | C8: 12G | D8: AM | E8: 43387 | F8: 15 | G8: Juvenile | H8: Gray | I8: Gray | J8: + | K8: Cinnamon back. Gray & Cinnamon selected as Primary. White selected as Highlights. Made executive adjustments. | L8: Ground Plane | M8: FALSE | N8: on tree trunk | O8: TRUE | P8: TRUE | Q8: TRUE | R8: TRUE | S8: FALSE | T8: TRUE | U8: FALSE | V8: FALSE | W8: FALSE | X8: TRUE | Y8: TRUE | Z8: FALSE | AA8: FALSE | AB8: small jumps | AC8: 12G-AM-836699-01
A9: -73.953929 | B9: 40.794809 | C9: 18G | D9: AM | E9: 43386 | F9: 1 | G9: ? | H9: Black | I9: Black, Cinnamon, White | J9: Cinnamon+Gray, Black | K9: Beautiful white puff at the end of its tail | L9: Ground Plane | M9: FALSE | N9: on a checker table | O9: TRUE | P9: TRUE | Q9: FALSE | R9: TRUE | S9: TRUE | T9: TRUE | U9: TRUE | V9: FALSE | W9: TRUE | X9: FALSE | Y9: TRUE | Z9: FALSE | AA9: TRUE | AB9: pulling things off branches | AC9: 18G-AM-935471-09
A10: -73.962261 | B10: 40.773701 | C10: 40C | D10: AM | E10: 43386 | F10: 1 | G10: Juvenile | H10: Gray | I10: Gray, Black | J10: Gray+Black | K10: Cinnamon head | L10: Ground Plane | M10: FALSE | N10: lower branch of tree | O10: TRUE | P10: TRUE | Q10: TRUE | R10: FALSE | S10: FALSE | T10: TRUE | U10: FALSE | V10: TRUE | W10: FALSE | X10: TRUE | Y10: TRUE | Z10: TRUE | AA10: FALSE | AB10: for food | AC10: 40C-AM-462793-29
A11: -73.958899 | B11: 40.782142 | C11: 18I | D11: AM | E11: 43379 | F11: 25 | G11: Juvenile | H11: Black | I11: Black, Cinnamon, White | J11: Gray+ | K11: unknown - cannot see, only hear | L11: Above Ground | M11: 12 | N11: Behind fence, tree trunk | O11: TRUE | P11: TRUE | Q11: TRUE | R11: FALSE | S11: TRUE | T11: TRUE | U11: FALSE | V11: FALSE | W11: FALSE | X11: FALSE | Y11: FALSE | Z11: TRUE | AA11: TRUE | AB11: climbing fence! | AC11: 18I-AM-816748-16
A12: -73.980511 | B12: 40.772699 | C12: 22B | D12: AM | E12: 43391 | F12: 10 | G12: Adult | H12: Black | I12: Gray, White | J12: Gray+Black, Cinnamon | K12: No Tail! | L12: Ground Plane | M12: FALSE | N12: Running along stone ledge | O12: TRUE | P12: FALSE | Q12: TRUE | R12: FALSE | S12: FALSE | T12: FALSE | U12: TRUE | V12: TRUE | W12: FALSE | X12: TRUE | Y12: FALSE | Z12: TRUE | AA12: FALSE | AB12: laid down on the branch | AC12: 22B-AM-103005-20
A13: -73.950668 | B13: 40.799684 | C13: 40B | D13: AM | E13: 43387 | F13: 22 | G13: ? | H13: Gray | I13: White | J13: Gray+Cinnamon, White | K13: patches of white on haunches | L13: Ground Plane | M13: FALSE | N13: Ground & Tree Base | O13: FALSE | P13: FALSE | Q13: FALSE | R13: FALSE | S13: TRUE | T13: TRUE | U13: TRUE | V13: TRUE | W13: TRUE | X13: FALSE | Y13: FALSE | Z13: FALSE | AA13: TRUE | AB13: very quietly searching in long grass | AC13: 40B-AM-378364-25
A14: -73.954989 | B14: 40.798149 | C14: 18E | D14: AM | E14: 43384 | F14: 10 | G14: Adult | H14: Black | I14: Gray, Black | J14: Black+Gray | K14: Gray on legs | L14: Ground Plane | M14: FALSE | N14: road | O14: TRUE | P14: FALSE | Q14: FALSE | R14: TRUE | S14: FALSE | T14: TRUE | U14: TRUE | V14: FALSE | W14: FALSE | X14: FALSE | Y14: TRUE | Z14: FALSE | AA14: TRUE | AB14: foraging (foraged,ran to tree root,munched) | AC14: 18E-AM-835043-14
A15: -73.974483 | B15: 40.766299 | C15: 25I | D15: PM | E15: 43387 | F15: 21 | G15: Adult | H15: Black | I15: Gray, Black | J15: Cinnamon+Gray, Black | K15: Cinnamon on shoulders | L15: Ground Plane | M15: FALSE | N15: Elm tree | O15: FALSE | P15: TRUE | Q15: FALSE | R15: TRUE | S15: FALSE | T15: TRUE | U15: TRUE | V15: FALSE | W15: FALSE | X15: TRUE | Y15: TRUE | Z15: TRUE | AA15: FALSE | AB15: chasing #15 | AC15: 25I-PM-622779-05
A16: -73.975443 | B16: 40.789752 | C16: 08I | D16: PM | E16: 43381 | F16: 15 | G16: ? | H16: Black | I16: White | J16: Black+Cinnamon | K16: Gray & Cinnamon selected as Primary. White selected as Highlights. Made executive adjustments. | L16: Ground Plane | M16: FALSE | N16: on fallen tree | O16: FALSE | P16: TRUE | Q16: FALSE | R16: TRUE | S16: TRUE | T16: TRUE | U16: TRUE | V16: FALSE | W16: FALSE | X16: TRUE | Y16: FALSE | Z16: FALSE | AA16: FALSE | AB16: standing | AC16: 08I-PM-231148-25
A17: -73.975393 | B17: 40.797487 | C17: 19H | D17: AM | E17: 43390 | F17: 17 | G17: ? | H17: Cinnamon | I17: Black | J17: Gray+Cinnamon, White | K17: primary color: brown ( I marked cinnamon as closest to brown - JO) | L17: Above Ground | M17: 10 | N17: under bench | O17: FALSE | P17: FALSE | Q17: FALSE | R17: TRUE | S17: FALSE | T17: TRUE | U17: TRUE | V17: TRUE | W17: FALSE | X17: FALSE | Y17: FALSE | Z17: TRUE | AA17: TRUE | AB17: chillin' | AC17: 19H-AM-250018-05
A18: -73.971594 | B18: 40.771268 | C18: 06F | D18: PM | E18: 43381 | F18: 22 | G18: ? | H18: Gray | I18: White | J18: Cinnamon+Gray, Black | K18: Listed as primary white with cinnamon highlights, I changed to Gray/cinnamon - JO | L18: Ground Plane | M18: FALSE | N18: high in tree, couldn't see it, only heard it | O18: TRUE | P18: TRUE | Q18: FALSE | R18: TRUE | S18: FALSE | T18: TRUE | U18: FALSE | V18: FALSE | W18: TRUE | X18: TRUE | Y18: TRUE | Z18: TRUE | AA18: TRUE | AB18: up on hind legs looking around | AC18: 06F-PM-909903-19
A19: -73.964662 | B19: 40.784907 | C19: 24B | D19: AM | E19: 43384 | F19: 6 | G19: Juvenile | H19: Black | I19: Black, Cinnamon, White | J19: Gray+Cinnamon | K19: Gray, Black, & Cinnamon selected as Primary. Cinnamon & White selected as Highlights. Made executive adjustments. | L19: Above Ground | M19: 12 | N19: oak tree at end of ramp from Chess House | O19: FALSE | P19: FALSE | Q19: FALSE | R19: TRUE | S19: TRUE | T19: TRUE | U19: TRUE | V19: TRUE | W19: FALSE | X19: TRUE | Y19: FALSE | Z19: TRUE | AA19: FALSE | AB19: jumping | AC19: 24B-AM-554747-19
A20: -73.96758 | B20: 40.797143 | C20: 38H | D20: AM | E20: 43387 | F20: 3 | G20: ? | H20: Gray | I20: Gray, White | J20: Cinnamon+Gray | K20: Looks very brown, not like English red squirrels | L20: Ground Plane | M20: FALSE | N20: on railing | O20: FALSE | P20: FALSE | Q20: TRUE | R20: FALSE | S20: TRUE | T20: TRUE | U20: TRUE | V20: TRUE | W20: TRUE | X20: FALSE | Y20: FALSE | Z20: TRUE | AA20: TRUE | AB20: hiding from bird | AC20: 38H-AM-271792-18
A21: -73.972003 | B21: 40.766106 | C21: 08G | D21: PM | E21: 43385 | F21: 13 | G21: ? | H21: Gray | I21: Cinnamon, White | J21: Cinnamon+Black, White | K21: Gray & Cinnamon selected as Primary. Gray & White selected as Highlights. Made executive adjustments. | L21: Ground Plane | M21: FALSE | N21: middle of grass | O21: TRUE | P21: FALSE | Q21: FALSE | R21: TRUE | S21: TRUE | T21: FALSE | U21: TRUE | V21: FALSE | W21: TRUE | X21: FALSE | Y21: TRUE | Z21: TRUE | AA21: TRUE | AB21: playing tag together | AC21: 08G-PM-614513-25
A22: -73.961924 | B22: 40.789465 | C22: 12I | D22: AM | E22: 43392 | F22: 16 | G22: ? | H22: Gray | I22: Black | J22: Gray+ | K22: Sighting was far away | L22: Ground Plane | M22: FALSE | N22: Baseball field #3 | O22: FALSE | P22: FALSE | Q22: TRUE | R22: TRUE | S22: TRUE | T22: FALSE | U22: TRUE | V22: FALSE | W22: FALSE | X22: TRUE | Y22: TRUE | Z22: TRUE | AA22: FALSE | AB22: burying nuts | AC22: 12I-AM-374006-08
A23: -73.976773 | B23: 40.77538 | C23: 14I | D23: AM | E23: 43391 | F23: 8 | G23: Adult | H23: Black | I23: Black, White | J23: Black+Gray | K23: too far to note 30' | L23: Above Ground | M23: 15 | N23: in the European Beech | O23: FALSE | P23: TRUE | Q23: TRUE | R23: TRUE | S23: TRUE | T23: TRUE | U23: FALSE | V23: FALSE | W23: FALSE | X23: TRUE | Y23: FALSE | Z23: FALSE | AA23: TRUE | AB23: playing w/ #7 | AC23: 14I-AM-168273-09
A24: -73.971974 | B24: 40.797457 | C24: 16F | D24: PM | E24: 43381 | F24: 30 | G24: Adult | H24: Black | I24: Cinnamon, White | J24: Gray+Black | K24: had .5 of a tail | L24: Ground Plane | M24: FALSE | N24: in a tree | O24: FALSE | P24: FALSE | Q24: FALSE | R24: FALSE | S24: TRUE | T24: FALSE | U24: TRUE | V24: FALSE | W24: TRUE | X24: FALSE | Y24: FALSE | Z24: FALSE | AA24: TRUE | AB24: flying | AC24: 16F-PM-646076-19
A25: -73.969641 | B25: 40.7991 | C25: 36H | D25: PM | E25: 43381 | F25: 15 | G25: Juvenile | H25: Gray | I25: Cinnamon | J25: Gray+Black | K25: (very brown) | L25: Above Ground | M25: 5 | N25: up a tree | O25: TRUE | P25: TRUE | Q25: FALSE | R25: TRUE | S25: FALSE | T25: FALSE | U25: TRUE | V25: TRUE | W25: FALSE | X25: FALSE | Y25: FALSE | Z25: FALSE | AA25: FALSE | AB25: chasing (#7) | AC25: 36H-PM-170185-29
A26: -73.966821 | B26: 40.798156 | C26: 22B | D26: AM | E26: 43380 | F26: 17 | G26: Adult | H26: Cinnamon | I26: Cinnamon | J26: Black+Gray | K26: Can't tell :( | L26: Above Ground | M26: 12 | N26: elevated ground | O26: FALSE | P26: FALSE | Q26: TRUE | R26: TRUE | S26: FALSE | T26: FALSE | U26: FALSE | V26: FALSE | W26: FALSE | X26: FALSE | Y26: FALSE | Z26: TRUE | AA26: TRUE | AB26: buried nut | AC26: 22B-AM-807649-28
A27: -73.956475 | B27: 40.781607 | C27: 40E | D27: PM | E27: 43387 | F27: 17 | G27: Juvenile | H27: Gray | I27: Cinnamon | J27: Cinnamon+ | K27: Cinnamon & White selected as Primary. Cinnamon & White selected as Highlights. Made executive adjustments. | L27: Ground Plane | M27: FALSE | N27: high in tree, couldn't see it, only heard it | O27: FALSE | P27: FALSE | Q27: TRUE | R27: TRUE | S27: FALSE | T27: FALSE | U27: FALSE | V27: TRUE | W27: FALSE | X27: FALSE | Y27: TRUE | Z27: TRUE | AA27: FALSE | AB27: together w/ #8 | AC27: 40E-PM-763184-25
A28: -73.974881 | B28: 40.795261 | C28: 01B | D28: PM | E28: 43391 | F28: 22 | G28: Adult | H28: Cinnamon | I28: Cinnamon | J28: Gray+Cinnamon | K28: Tiny! So tiny! | L28: Above Ground | M28: 8 | N28: in tall shrubs near wall next to CPW | O28: TRUE | P28: FALSE | Q28: FALSE | R28: FALSE | S28: TRUE | T28: FALSE | U28: FALSE | V28: FALSE | W28: TRUE | X28: FALSE | Y28: FALSE | Z28: TRUE | AA28: FALSE | AB28: climbing (tree) | AC28: 01B-PM-107799-13
A29: -73.964993 | B29: 40.794645 | C29: 09D | D29: AM | E29: 43393 | F29: 26 | G29: ? | H29: Gray | I29: Gray, White | J29: Cinnamon+Black, White | K29: Gray & Cinnamon selected as both Primary and Highlights. Made executive adjustments. | L29: Ground Plane | M29: FALSE | N29: In the Woods/Brush | O29: TRUE | P29: FALSE | Q29: TRUE | R29: TRUE | S29: TRUE | T29: FALSE | U29: TRUE | V29: FALSE | W29: TRUE | X29: FALSE | Y29: FALSE | Z29: FALSE | AA29: TRUE | AB29: going down tree | AC29: 09D-AM-709694-28
A30: -73.962535 | B30: 40.776146 | C30: 29B | D30: PM | E30: 43381 | F30: 13 | G30: Adult | H30: Gray | I30: Cinnamon, White | J30: Gray+Black, Cinnamon | K30: small adult | L30: Ground Plane | M30: FALSE | N30: Open ground | O30: FALSE | P30: TRUE | Q30: TRUE | R30: TRUE | S30: FALSE | T30: TRUE | U30: FALSE | V30: FALSE | W30: FALSE | X30: FALSE | Y30: TRUE | Z30: TRUE | AA30: TRUE | AB30: communicating from tree | AC30: 29B-PM-882703-20
A31: -73.979698 | B31: 40.794095 | C31: 02H | D31: PM | E31: 43389 | F31: 17 | G31: Juvenile | H31: Gray | I31: Black, Cinnamon | J31: Black+White | K31: my favorite | L31: Above Ground | M31: 6 | N31: bushes | O31: TRUE | P31: TRUE | Q31: TRUE | R31: FALSE | S31: FALSE | T31: TRUE | U31: FALSE | V31: TRUE | W31: FALSE | X31: FALSE | Y31: TRUE | Z31: FALSE | AA31: FALSE | AB31: jumping between branches | AC31: 02H-PM-895046-28
A32: -73.962059 | B32: 40.766214 | C32: 22D | D32: AM | E32: 43383 | F32: 6 | G32: Adult | H32: Black | I32: Gray | J32: Gray+Black | K32: just outside hectare | L32: Ground Plane | M32: FALSE | N32: Running from one tree to the other | O32: TRUE | P32: TRUE | Q32: TRUE | R32: TRUE | S32: TRUE | T32: FALSE | U32: FALSE | V32: FALSE | W32: TRUE | X32: TRUE | Y32: TRUE | Z32: TRUE | AA32: FALSE | AB32: sitting still | AC32: 22D-AM-438781-03
A33: -73.975798 | B33: 40.785904 | C33: 16A | D33: PM | E33: 43392 | F33: 17 | G33: ? | H33: Cinnamon | I33: Black | J33: Black+Gray | K33: No Primary Fur Color selected. Made executive adjustment based on other squirrels. | L33: Ground Plane | M33: FALSE | N33: Jumped onto path & then back into brush | O33: TRUE | P33: TRUE | Q33: FALSE | R33: FALSE | S33: FALSE | T33: TRUE | U33: TRUE | V33: TRUE | W33: TRUE | X33: TRUE | Y33: TRUE | Z33: FALSE | AA33: TRUE | AB33: nest building | AC33: 16A-PM-120914-20
A34: -73.979114 | B34: 40.773009 | C34: 06B | D34: PM | E34: 43392 | F34: 16 | G34: Juvenile | H34: Cinnamon | I34: Black, White | J34: Cinnamon+White | K34: Gray, Black, & Cinnamon selected as Primary. Cinnamon & White selected as Highlights. Made executive adjustments. | L34: Above Ground | M34: 6 | N34: On rock | O34: TRUE | P34: FALSE | Q34: FALSE | R34: TRUE | S34: TRUE | T34: FALSE | U34: TRUE | V34: FALSE | W34: TRUE | X34: TRUE | Y34: TRUE | Z34: TRUE | AA34: FALSE | AB34: climbing down | AC34: 06B-PM-371759-02
A35: -73.951329 | B35: 40.769156 | C35: 14D | D35: AM | E35: 43387 | F35: 14 | G35: ? | H35: Gray | I35: Black, Cinnamon, White | J35: Cinnamon+ | K35: White back left leg | L35: Above Ground | M35: 2 | N35: Ground & Tree Base | O35: TRUE | P35: TRUE | Q35: TRUE | R35: FALSE | S35: TRUE | T35: TRUE | U35: FALSE | V35: FALSE | W35: TRUE | X35: FALSE | Y35: TRUE | Z35: TRUE | AA35: TRUE | AB35: playing w/ #7 | AC35: 14D-AM-450733-26
A36: -73.950802 | B36: 40.76762 | C36: 06E | D36: AM | E36: 43386 | F36: 13 | G36: ? | H36: Black | I36: Gray, Black | J36: Black+ | K36: Gray, Cinnamon & White selected as Primary. White selected as Highlights. Made executive adjustments. | L36: Above Ground | M36: 3 | N36: climbing in bush | O36: TRUE | P36: TRUE | Q36: TRUE | R36: TRUE | S36: FALSE | T36: TRUE | U36: TRUE | V36: TRUE | W36: TRUE | X36: TRUE | Y36: TRUE | Z36: FALSE | AA36: FALSE | AB36: ran across a path | AC36: 06E-AM-551027-10
A37: -73.955745 | B37: 40.789426 | C37: 02E | D37: AM | E37: 43380 | F37: 6 | G37: Juvenile | H37: Black | I37: Cinnamon | J37: Cinnamon+Gray | K37: No Primary Fur Color selected. Made executive adjustment based on other squirrels. | L37: Above Ground | M37: 15 | N37: in tree! | O37: TRUE | P37: FALSE | Q37: TRUE | R37: TRUE | S37: TRUE | T37: TRUE | U37: TRUE | V37: TRUE | W37: TRUE | X37: FALSE | Y37: FALSE | Z37: FALSE | AA37: FALSE | AB37: got fed twice by grandpa,grabbed from grass and ate in tree | AC37: 02E-AM-409042-24
A38: -73.971582 | B38: 40.776877 | C38: 41G | D38: PM | E38: 43381 | F38: 3 | G38: ? | H38: Cinnamon | I38: Black, White | J38: Cinnamon+Gray | K38: Nothing selected as Primary. Gray selected as Highlights. Made executive adjustments. | L38: Above Ground | M38: 4 | N38: Shore | O38: FALSE | P38: TRUE | Q38: FALSE | R38: FALSE | S38: TRUE | T38: FALSE | U38: TRUE | V38: FALSE | W38: TRUE | X38: TRUE | Y38: FALSE | Z38: FALSE | AA38: FALSE | AB38: for food | AC38: 41G-PM-995850-18
A39: -73.978088 | B39: 40.790428 | C39: 12I | D39: AM | E39: 43380 | F39: 14 | G39: ? | H39: Black | I39: Gray, Black | J39: Gray+Black, Cinnamon, White | K39: didn't get a good look | L39: Above Ground | M39: 40 | N39: Different tree | O39: TRUE | P39: TRUE | Q39: FALSE | R39: TRUE | S39: TRUE | T39: TRUE | U39: TRUE | V39: FALSE | W39: FALSE | X39: FALSE | Y39: TRUE | Z39: TRUE | AA39: TRUE | AB39: scanning (drawing included) | AC39: 12I-AM-176031-11
A40: -73.959648 | B40: 40.767212 | C40: 37D | D40: AM | E40: 43386 | F40: 14 | G40: Adult | H40: Cinnamon | I40: Gray | J40: Gray+Black, White | K40: White belly & stripes on tail, Cinnamon face & stripes on back | L40: Ground Plane | M40: FALSE | N40: Tree cavity [of] London Plane tree | O40: TRUE | P40: TRUE | Q40: TRUE | R40: TRUE | S40: TRUE | T40: TRUE | U40: TRUE | V40: TRUE | W40: TRUE | X40: FALSE | Y40: FALSE | Z40: FALSE | AA40: FALSE | AB40: different sound - happy,playful chirps | AC40: 37D-AM-485096-19
...

Sheet Empirical_Random_Squirrel_Data
A1: X | B1: Y | C1: Hectare | D1: Shift | E1: Date | F1: Hectare Squirrel Number | G1: Age | H1: Primary Fur Color | I1: Highlight Fur Color | J1: Combination of Primary and Highlight Color | K1: Color notes | L1: Location | M1: Above Ground Sighter Measurement | N1: Specific Location | O1: Running | P1: Chasing | Q1: Climbing | R1: Eating | S1: Foraging | T1: Kuks | U1: Quaas | V1: Moans | W1: Tail flags | X1: Tail twitches | Y1: Approaches | Z1: Indifferent | AA1: Runs from | AB1: Other Activities | AC1: Unique Squirrel ID
A2: -73.969384 | B2: 40.771429 | C2: 41B | D2: AM | E2: 43388 | F2: 2 | G2: Adult | H2: Gray | I2: Cinnamon | J2: Gray+Black, Cinnamon, White | K2: Partial missing tail | L2: Ground Plane | M2: FALSE | N2: walking along path | O2: FALSE | P2: FALSE | Q2: FALSE | R2: FALSE | S2: TRUE | T2: FALSE | U2: FALSE | V2: FALSE | W2: FALSE | X2: FALSE | Y2: FALSE | Z2: TRUE | AA2: FALSE | AB2: standing upright | AC2: 41B-AM-981253-28
A3: -73.951271 | B3: 40.78399 | C3: 38E | D3: AM | E3: 43383 | F3: 25 | G3: Adult | H3: Gray | I3: White | J3: Gray+ | K3: Off-white, decorator's white? | L3: Ground Plane | M3: FALSE | N3: on tree trunk (descending from height of ~10 ft) | O3: FALSE | P3: FALSE | Q3: FALSE | R3: FALSE | S3: FALSE | T3: FALSE | U3: FALSE | V3: FALSE | W3: FALSE | X3: TRUE | Y3: FALSE | Z3: FALSE | AA3: FALSE | AB3: running (from a dog) | AC3: 38E-AM-156733-18
A4: -73.958147 | B4: 40.795645 | C4: 21E | D4: PM | E4: 43383 | F4: 29 | G4: Adult | H4: Gray | I4: Cinnamon | J4: Gray+Cinnamon | K4: Cinnamon head & stripe | L4: Ground Plane | M4: FALSE | N4: Under the tree | O4: FALSE | P4: FALSE | Q4: FALSE | R4: FALSE | S4: TRUE | T4: FALSE | U4: FALSE | V4: FALSE | W4: FALSE | X4: FALSE | Y4: FALSE | Z4: TRUE | AA4: FALSE | AB4: burying | AC4: 21E-PM-764536-24
A5: -73.962339 | B5: 40.790691 | C5: 38E | D5: AM | E5: 43389 | F5: 13 | G5: Adult | H5: Gray | I5: White | J5: Gray+Cinnamon | K5: Partial missing tail | L5: Above Ground | M5: 6 | N5: under bushes | O5: FALSE | P5: FALSE | Q5: TRUE | R5: TRUE | S5: FALSE | T5: FALSE | U5: FALSE | V5: FALSE | W5: FALSE | X5: FALSE | Y5: FALSE | Z5: FALSE | AA5: FALSE | AB5: did not notice dog sitting a few yards away (10-20 ft) | AC5: 38E-AM-190909-20
A6: -73.976254 | B6: 40.793308 | C6: 07G | D6: AM | E6: 43385 | F6: 6 | G6: Juvenile | H6: Gray | I6: Cinnamon | J6: Gray+Cinnamon | K6: Gray & Cinnamon selected as Primary. White selected as Highlights. Made executive adjustments. | L6: Ground Plane | M6: FALSE | N6: Rock | O6: TRUE | P6: FALSE | Q6: FALSE | R6: FALSE | S6: FALSE | T6: FALSE | U6: FALSE | V6: FALSE | W6: FALSE | X6: FALSE | Y6: FALSE | Z6: FALSE | AA6: FALSE | AB6: wresting w/ branch | AC6: 07G-AM-980706-27
A7: -73.976255 | B7: 40.788105 | C7: 12H | D7: AM | E7: 43382 | F7: 21 | G7: Adult | H7: Gray | I7: Cinnamon | J7: Gray+White | K7: white back legs | L7: Above Ground | M7: 3 | N7: on a log | O7: TRUE | P7: FALSE | Q7: FALSE | R7: FALSE | S7: FALSE | T7: FALSE | U7: FALSE | V7: FALSE | W7: FALSE | X7: FALSE | Y7: FALSE | Z7: TRUE | AA7: FALSE | AB7: new movement flailing arms while foraging | AC7: 12H-AM-182439-19
A8: -73.979333 | B8: 40.789284 | C8: 09F | D8: AM | E8: 43391 | F8: 26 | G8: Adult | H8: Cinnamon | I8: Cinnamon | J8: Gray+Cinnamon | K8: Cinnamon on the tail | L8: Above Ground | M8: 3 | N8: on fence | O8: FALSE | P8: FALSE | Q8: FALSE | R8: FALSE | S8: TRUE | T8: FALSE | U8: FALSE | V8: FALSE | W8: FALSE | X8: TRUE | Y8: FALSE | Z8: FALSE | AA8: FALSE | AB8: jumping | AC8: 09F-AM-105041-15
A9: -73.953929 | B9: 40.794809 | C9: 16C | D9: PM | E9: 43382 | F9: 6 | G9: Adult | H9: Gray | I9: White | J9: Gray+Cinnamon | K9: white at end of tail | L9: Above Ground | M9: 12 | N9: near fence | O9: FALSE | P9: FALSE | Q9: FALSE | R9: FALSE | S9: TRUE | T9: FALSE | U9: FALSE | V9: FALSE | W9: FALSE | X9: FALSE | Y9: FALSE | Z9: FALSE | AA9: FALSE | AB9: playing with #5 | AC9: 16C-PM-582006-14
